<?xml version="1.0" encoding="utf-8"?>
<!-- This URDF was automatically created by SolidWorks to URDF Exporter! Originally created by Stephen Brawner (brawner@gmail.com) 
     Commit Version: 1.6.0-4-g7f85cfe  Build Version: 1.6.7995.38578
     For more information, please see http://wiki.ros.org/sw_urdf_exporter -->
<robot
  name="sanbot_nano_urdf">
  <link
    name="base_link">
    <inertial>
      <origin
        xyz="-1.64477253035522E-05 5.9312884606181E-06 0.0729321766717519"
        rpy="0 0 0" />
      <mass
        value="12.9158989489561" />
      <inertia
        ixx="0.11281645397611"
        ixy="-2.49617328764964E-05"
        ixz="-3.29336671339687E-05"
        iyy="0.11397342921281"
        iyz="5.30882435321549E-07"
        izz="0.213909779379668" />
    </inertial>
    <visual>
      <origin
        xyz="0 0 0"
        rpy="0 0 0" />
      <geometry>
        <mesh
          filename="package://sanbot_nano_urdf/meshes/base_link.STL" />
      </geometry>
      <material
        name="">
        <color
          rgba="1 1 1 1" />
      </material>
    </visual>
    <collision>
      <origin
        xyz="0 0 0"
        rpy="0 0 0" />
      <geometry>
        <mesh
          filename="package://sanbot_nano_urdf/meshes/base_link.STL" />
      </geometry>
    </collision>
  </link>
  <link
    name="wheel_1_link">
    <inertial>
      <origin
        xyz="-1.9572E-08 1.6882E-07 0.017969"
        rpy="0 0 0" />
      <mass
        value="0.31873" />
      <inertia
        ixx="9.2012E-05"
        ixy="-3.9404E-16"
        ixz="-1.1959E-20"
        iyy="9.2012E-05"
        iyz="4.0111E-21"
        izz="0.0001705" />
    </inertial>
    <visual>
      <origin
        xyz="0 0 0"
        rpy="0 0 0" />
      <geometry>
        <mesh
          filename="package://sanbot_nano_urdf/meshes/wheel_1_link.STL" />
      </geometry>
      <material
        name="">
        <color
          rgba="0.10196 0.10196 0.10196 1" />
      </material>
    </visual>
    <collision>
      <origin
        xyz="0 0 0"
        rpy="0 0 0" />
      <geometry>
        <mesh
          filename="package://sanbot_nano_urdf/meshes/wheel_1_link.STL" />
      </geometry>
    </collision>
  </link>
  <joint
    name="wheel_1"
    type="continuous">
    <origin
      xyz="0.1195 0 0.03"
      rpy="1.5708 0 1.5708" />
    <parent
      link="base_link" />
    <child
      link="wheel_1_link" />
    <axis
      xyz="0 0 1" />
  </joint>
  <link
    name="wheel_2_link">
    <inertial>
      <origin
        xyz="-0.0155613556791648 -1.36414627743137E-07 -0.00898423585151896"
        rpy="0 0 0" />
      <mass
        value="0.318731676051724" />
      <inertia
        ixx="0.000150881393626606"
        ixy="-4.81220593158849E-20"
        ixz="3.39880992947803E-05"
        iyy="9.20122787944416E-05"
        iyz="7.2738954345463E-20"
        izz="0.000111635317072437" />
    </inertial>
    <visual>
      <origin
        xyz="0 0 0"
        rpy="0 0 0" />
      <geometry>
        <mesh
          filename="package://sanbot_nano_urdf/meshes/wheel_2_link.STL" />
      </geometry>
      <material
        name="">
        <color
          rgba="0.101960784313725 0.101960784313725 0.101960784313725 1" />
      </material>
    </visual>
    <collision>
      <origin
        xyz="0 0 0"
        rpy="0 0 0" />
      <geometry>
        <mesh
          filename="package://sanbot_nano_urdf/meshes/wheel_2_link.STL" />
      </geometry>
    </collision>
  </link>
  <joint
    name="wheel_2"
    type="continuous">
    <origin
      xyz="-0.05975 -0.10349 0.03"
      rpy="1.5708 0 1.5708" />
    <parent
      link="base_link" />
    <child
      link="wheel_2_link" />
    <axis
      xyz="-0.86603 0 -0.5" />
  </joint>
  <link
    name="wheel_3_link">
    <inertial>
      <origin
        xyz="0.0155629154939929 2.62956446859045E-06 -0.00898153417298637"
        rpy="0 0 0" />
      <mass
        value="0.318731676051724" />
      <inertia
        ixx="0.000150881393626607"
        ixy="-1.12443623748008E-19"
        ixz="-3.39880992947797E-05"
        iyy="9.20122787944418E-05"
        iyz="-1.84282605587014E-19"
        izz="0.000111635317072436" />
    </inertial>
    <visual>
      <origin
        xyz="0 0 0"
        rpy="0 0 0" />
      <geometry>
        <mesh
          filename="package://sanbot_nano_urdf/meshes/wheel_3_link.STL" />
      </geometry>
      <material
        name="">
        <color
          rgba="0.101960784313725 0.101960784313725 0.101960784313725 1" />
      </material>
    </visual>
    <collision>
      <origin
        xyz="0 0 0"
        rpy="0 0 0" />
      <geometry>
        <mesh
          filename="package://sanbot_nano_urdf/meshes/wheel_3_link.STL" />
      </geometry>
    </collision>
  </link>
  <joint
    name="wheel_3"
    type="continuous">
    <origin
      xyz="-0.059753 0.10349 0.029998"
      rpy="1.5708 0 1.5708" />
    <parent
      link="base_link" />
    <child
      link="wheel_3_link" />
    <axis
      xyz="0.86603 0 -0.5" />
  </joint>
  <link
    name=" body_link">
    <inertial>
      <origin
        xyz="7.5821657898137E-06 0.187923033888507 0.00047673713129741"
        rpy="0 0 0" />
      <mass
        value="37.769228971116" />
      <inertia
        ixx="0.759270181933302"
        ixy="-5.92484661876993E-06"
        ixz="2.49839659342806E-07"
        iyy="0.622168661439397"
        iyz="0.0320158424753172"
        izz="0.784453124434141" />
    </inertial>
    <visual>
      <origin
        xyz="0 0 0"
        rpy="0 0 0" />
      <geometry>
        <mesh
          filename="package://sanbot_nano_urdf/meshes/ body_link.STL" />
      </geometry>
      <material
        name="">
        <color
          rgba="1 1 1 1" />
      </material>
    </visual>
    <collision>
      <origin
        xyz="0 0 0"
        rpy="0 0 0" />
      <geometry>
        <mesh
          filename="package://sanbot_nano_urdf/meshes/ body_link.STL" />
      </geometry>
    </collision>
  </link>
  <joint
    name="body"
    type="fixed">
    <origin
      xyz="0 0 0.14"
      rpy="1.5707963267949 0 1.5707963267949" />
    <parent
      link="base_link" />
    <child
      link=" body_link" />
    <axis
      xyz="0 0 0" />
  </joint>
  <link
    name="wing_left_link">
    <inertial>
      <origin
        xyz="-0.0160606525902144 -0.0598406170368806 -0.00919707200658264"
        rpy="0 0 0" />
      <mass
        value="0.328951203332961" />
      <inertia
        ixx="0.00142200116993639"
        ixy="-8.64723104371909E-06"
        ixz="-1.32901460486538E-06"
        iyy="0.000406493634908928"
        iyz="-8.53334155343087E-05"
        izz="0.00102782493969589" />
    </inertial>
    <visual>
      <origin
        xyz="0 0 0"
        rpy="0 0 0" />
      <geometry>
        <mesh
          filename="package://sanbot_nano_urdf/meshes/wing_left_link.STL" />
      </geometry>
      <material
        name="">
        <color
          rgba="1 1 1 1" />
      </material>
    </visual>
    <collision>
      <origin
        xyz="0 0 0"
        rpy="0 0 0" />
      <geometry>
        <mesh
          filename="package://sanbot_nano_urdf/meshes/wing_left_link.STL" />
      </geometry>
    </collision>
  </link>
  <joint
    name="wing_left"
    type="revolute">
    <origin
      xyz="-0.171 0.338 -0.0087685"
      rpy="0 0 0" />
    <parent
      link=" body_link" />
    <child
      link="wing_left_link" />
    <axis
      xyz="1 0 0" />
    <limit
      lower="-1.5708"
      upper="3.1416"
      effort="10"
      velocity="1" />
  </joint>
  <link
    name="wing_right_link">
    <inertial>
      <origin
        xyz="0.0160606529414991 -0.0598405732596894 -0.00919681533921747"
        rpy="0 0 0" />
      <mass
        value="0.328951060786706" />
      <inertia
        ixx="0.00142201224183235"
        ixy="8.64758632358562E-06"
        ixz="1.32905476796954E-06"
        iyy="0.000406493994406582"
        iyz="-8.53346894541831E-05"
        izz="0.00102783571361827" />
    </inertial>
    <visual>
      <origin
        xyz="0 0 0"
        rpy="0 0 0" />
      <geometry>
        <mesh
          filename="package://sanbot_nano_urdf/meshes/wing_right_link.STL" />
      </geometry>
      <material
        name="">
        <color
          rgba="1 1 1 1" />
      </material>
    </visual>
    <collision>
      <origin
        xyz="0 0 0"
        rpy="0 0 0" />
      <geometry>
        <mesh
          filename="package://sanbot_nano_urdf/meshes/wing_right_link.STL" />
      </geometry>
    </collision>
  </link>
  <joint
    name="wing_right"
    type="revolute">
    <origin
      xyz="0.171 0.338 -0.0087685"
      rpy="0 0 0" />
    <parent
      link=" body_link" />
    <child
      link="wing_right_link" />
    <axis
      xyz="-1 0 0" />
    <limit
      lower="-1.5708"
      upper="3.1416"
      effort="10"
      velocity="1" />
  </joint>
  <link
    name="neck_link">
    <inertial>
      <origin
        xyz="-0.00366319374296106 0.0167913597709003 2.99564466910598E-18"
        rpy="0 0 0" />
      <mass
        value="0.077278069019187" />
      <inertia
        ixx="1.80765069210195E-05"
        ixy="-4.65106610937673E-22"
        ixz="-2.90539801128703E-21"
        iyy="8.60362454625531E-05"
        iyz="-3.34857161537838E-22"
        izz="9.15677880195827E-05" />
    </inertial>
    <visual>
      <origin
        xyz="0 0 0"
        rpy="0 0 0" />
      <geometry>
        <mesh
          filename="package://sanbot_nano_urdf/meshes/neck_link.STL" />
      </geometry>
      <material
        name="">
        <color
          rgba="1 1 1 1" />
      </material>
    </visual>
    <collision>
      <origin
        xyz="0 0 0"
        rpy="0 0 0" />
      <geometry>
        <mesh
          filename="package://sanbot_nano_urdf/meshes/neck_link.STL" />
      </geometry>
    </collision>
  </link>
  <joint
    name="neck"
    type="revolute">
    <origin
      xyz="0 0.3344 0"
      rpy="0 0 0" />
    <parent
      link=" body_link" />
    <child
      link="neck_link" />
    <axis
      xyz="0 -1 0" />
    <limit
      lower="-1.5708"
      upper="1.5708"
      effort="10"
      velocity="1" />
  </joint>
  <link
    name="head_link">
    <inertial>
      <origin
        xyz="-0.00365422427131145 0.181550277076497 -0.00307847722307662"
        rpy="0 0 0" />
      <mass
        value="15.6411788909065" />
      <inertia
        ixx="0.158830287109258"
        ixy="-1.6359491177653E-07"
        ixz="1.44250529127581E-06"
        iyy="0.157816658158948"
        iyz="0.0132319198738727"
        izz="0.163690241546174" />
    </inertial>
    <visual>
      <origin
        xyz="0 0 0"
        rpy="0 0 0" />
      <geometry>
        <mesh
          filename="package://sanbot_nano_urdf/meshes/head_link.STL" />
      </geometry>
      <material
        name="">
        <color
          rgba="1 1 1 1" />
      </material>
    </visual>
    <collision>
      <origin
        xyz="0 0 0"
        rpy="0 0 0" />
      <geometry>
        <mesh
          filename="package://sanbot_nano_urdf/meshes/head_link.STL" />
      </geometry>
    </collision>
  </link>
  <joint
    name="head"
    type="revolute">
    <origin
      xyz="0 0.02 0"
      rpy="0 0 0" />
    <parent
      link="neck_link" />
    <child
      link="head_link" />
    <axis
      xyz="-1 0 0" />
    <limit
      lower="0"
      upper="0.656"
      effort="10"
      velocity="1" />
  </joint>
</robot>