<?xml version="1.0" encoding="utf-8"?>
<!-- This URDF was automatically created by SolidWorks to URDF Exporter! Originally created by Stephen Brawner (brawner@gmail.com) 
     Commit Version: 1.6.0-4-g7f85cfe  Build Version: 1.6.7995.38578
     For more information, please see http://wiki.ros.org/sw_urdf_exporter -->
<robot
  name="sanbot_nano_urdf">
  <link
    name="base_link">
    <inertial>
      <origin
        xyz="-1.64477253035514E-05 5.93128846061808E-06 0.0729321766717519"
        rpy="0 0 0" />
      <mass
        value="6.0" />
      <inertia
        ixx="0.11281645397611"
        ixy="-2.49617328764964E-05"
        ixz="-3.29336671339687E-05"
        iyy="0.11397342921281"
        iyz="5.30882435321518E-07"
        izz="0.213909779379668" />
    </inertial>
    <visual>
      <origin
        xyz="0 0 0"
        rpy="0 0 0" />
      <geometry>
        <mesh
          filename="package://sanbot_nano_urdf/meshes/base_link.STL" />
      </geometry>
      <material
        name="">
        <color
          rgba="1 1 1 1" />
      </material>
    </visual>
    <collision>
      <origin
        xyz="0 0 0"
        rpy="0 0 0" />
      <geometry>
        <mesh
          filename="package://sanbot_nano_urdf/meshes/base_link.STL" />
      </geometry>
    </collision>
  </link>
  <link
    name="wheel_back_link">
    <inertial>
      <origin
        xyz="-1.9572E-08 1.6882E-07 0.017969"
        rpy="0 0 0" />
      <mass
        value="0.088" />
      <inertia
        ixx="9.2012E-05"
        ixy="-3.9404E-16"
        ixz="-1.2059E-20"
        iyy="9.2012E-05"
        iyz="4.0153E-21"
        izz="0.0001705" />
    </inertial>
    <visual>
      <origin
        xyz="0 0 0"
        rpy="0 0 0" />
      <geometry>
        <mesh
          filename="package://sanbot_nano_urdf/meshes/wheel_back_link.STL" />
      </geometry>
      <material
        name="">
        <color
          rgba="0.10196 0.10196 0.10196 1" />
      </material>
    </visual>
    <collision>
      <origin
        xyz="0 0 0"
        rpy="0 0 0" />
      <geometry>
        <mesh
          filename="package://sanbot_nano_urdf/meshes/wheel_back_link.STL" />
      </geometry>
    </collision>
  </link>
  <joint
    name="wheel_back"
    type="continuous">
    <origin
      xyz="0.1195 0 0.03"
      rpy="1.5707963267949 0 1.5707963267949" />
    <parent
      link="base_link" />
    <child
      link="wheel_back_link" />
    <axis
      xyz="0 0 1" />
  </joint>
  <link
    name="wheel_left_link">
    <inertial>
      <origin
        xyz="-0.015561 -1.3641E-07 -0.0089842"
        rpy="0 0 0" />
      <mass
        value="0.088" />
      <inertia
        ixx="0.00015088"
        ixy="-4.841E-20"
        ixz="3.3988E-05"
        iyy="9.2012E-05"
        iyz="7.37E-20"
        izz="0.00011164" />
    </inertial>
    <visual>
      <origin
        xyz="0 0 0"
        rpy="0 0 0" />
      <geometry>
        <mesh
          filename="package://sanbot_nano_urdf/meshes/wheel_left_link.STL" />
      </geometry>
      <material
        name="">
        <color
          rgba="0.10196 0.10196 0.10196 1" />
      </material>
    </visual>
    <collision>
      <origin
        xyz="0 0 0"
        rpy="0 0 0" />
      <geometry>
        <mesh
          filename="package://sanbot_nano_urdf/meshes/wheel_left_link.STL" />
      </geometry>
    </collision>
  </link>
  <joint
    name="wheel_left"
    type="continuous">
    <origin
      xyz="-0.0597500000000005 -0.10349003575224 0.03"
      rpy="1.5707963267949 0 1.5707963267949" />
    <parent
      link="base_link" />
    <child
      link="wheel_left_link" />
    <axis
      xyz="-0.866025403784436 0 -0.500000000000004" />
  </joint>
  <link
    name="wheel_right_link">
    <inertial>
      <origin
        xyz="0.015563 2.6296E-06 -0.0089815"
        rpy="0 0 0" />
      <mass
        value="0.088" />
      <inertia
        ixx="0.00015088"
        ixy="-1.1253E-19"
        ixz="-3.3988E-05"
        iyy="9.2012E-05"
        iyz="-1.8431E-19"
        izz="0.00011164" />
    </inertial>
    <visual>
      <origin
        xyz="0 0 0"
        rpy="0 0 0" />
      <geometry>
        <mesh
          filename="package://sanbot_nano_urdf/meshes/wheel_right_link.STL" />
      </geometry>
      <material
        name="">
        <color
          rgba="0.10196 0.10196 0.10196 1" />
      </material>
    </visual>
    <collision>
      <origin
        xyz="0 0 0"
        rpy="0 0 0" />
      <geometry>
        <mesh
          filename="package://sanbot_nano_urdf/meshes/wheel_right_link.STL" />
      </geometry>
    </collision>
  </link>
  <joint
    name="wheel_right"
    type="continuous">
    <origin
      xyz="-0.0597527016785317 0.103488475937413 0.0299975068501592"
      rpy="1.5707963267949 0 1.5707963267949" />
    <parent
      link="base_link" />
    <child
      link="wheel_right_link" />
    <axis
      xyz="0.866025403784443 0 -0.499999999999992" />
  </joint>
  <link
    name=" body_link">
    <inertial>
      <origin
        xyz="-6.5075E-07 0.17116 0.0053147"
        rpy="0 0 0" />
      <mass
        value="10.54" />
      <inertia
        ixx="0.62632"
        ixy="4.1388E-06"
        ixz="1.1748E-07"
        iyy="0.58352"
        iyz="-0.00076156"
        izz="0.65666" />
    </inertial>
    <visual>
      <origin
        xyz="0 0 0"
        rpy="0 0 0" />
      <geometry>
        <mesh
          filename="package://sanbot_nano_urdf/meshes/ body_link.STL" />
      </geometry>
      <material
        name="">
        <color
          rgba="1 1 1 1" />
      </material>
    </visual>
    <collision>
      <origin
        xyz="0 0 0"
        rpy="0 0 0" />
      <geometry>
        <mesh
          filename="package://sanbot_nano_urdf/meshes/ body_link.STL" />
      </geometry>
    </collision>
  </link>
  <joint
    name="body"
    type="fixed">
    <origin
      xyz="0 0 0.14"
      rpy="1.5707963267949 0 1.5707963267949" />
    <parent
      link="base_link" />
    <child
      link=" body_link" />
    <axis
      xyz="0 0 0" />
  </joint>
  <link
    name="wing_left_link">
    <inertial>
      <origin
        xyz="-0.018053 -0.060356 -0.0092009"
        rpy="0 0 0" />
      <mass
        value="0.09" />
      <inertia
        ixx="0.0014351"
        ixy="-1.114E-05"
        ixz="-1.7211E-06"
        iyy="0.00041041"
        iyz="-8.6947E-05"
        izz="0.0010385" />
    </inertial>
    <visual>
      <origin
        xyz="0 0 0"
        rpy="0 0 0" />
      <geometry>
        <mesh
          filename="package://sanbot_nano_urdf/meshes/wing_left_link.STL" />
      </geometry>
      <material
        name="">
        <color
          rgba="1 1 1 1" />
      </material>
    </visual>
    <collision>
      <origin
        xyz="0 0 0"
        rpy="0 0 0" />
      <geometry>
        <mesh
          filename="package://sanbot_nano_urdf/meshes/wing_left_link.STL" />
      </geometry>
    </collision>
  </link>
  <joint
    name="wing_left"
    type="revolute">
    <origin
      xyz="-0.171 0.337999997444124 -0.00876845650366815"
      rpy="0 0 0" />
    <parent
      link=" body_link" />
    <child
      link="wing_left_link" />
    <axis
      xyz="1 0 0" />
    <limit
      lower="-1.5708"
      upper="3.1416"
      effort="10"
      velocity="1" />
  </joint>
  <link
    name="wing_right_link">
    <inertial>
      <origin
        xyz="0.01806 -0.06039 -0.009202"
        rpy="0 0 0" />
      <mass
        value="0.09" />
      <inertia
        ixx="0.0014353"
        ixy="1.1131E-05"
        ixz="1.7199E-06"
        iyy="0.00041054"
        iyz="-8.6972E-05"
        izz="0.0010386" />
    </inertial>
    <visual>
      <origin
        xyz="0 0 0"
        rpy="0 0 0" />
      <geometry>
        <mesh
          filename="package://sanbot_nano_urdf/meshes/wing_right_link.STL" />
      </geometry>
      <material
        name="">
        <color
          rgba="1 1 1 1" />
      </material>
    </visual>
    <collision>
      <origin
        xyz="0 0 0"
        rpy="0 0 0" />
      <geometry>
        <mesh
          filename="package://sanbot_nano_urdf/meshes/wing_right_link.STL" />
      </geometry>
    </collision>
  </link>
  <joint
    name="wing_right"
    type="revolute">
    <origin
      xyz="0.171 0.337999997444124 -0.00876845650366815"
      rpy="0 0 0" />
    <parent
      link=" body_link" />
    <child
      link="wing_right_link" />
    <axis
      xyz="1 0 0" />
    <limit
      lower="-1.5708"
      upper="3.1416"
      effort="10"
      velocity="1" />
  </joint>
  <link
    name="neck_link">
    <inertial>
      <origin
        xyz="5.0796E-08 0.094182 -2.1544E-07"
        rpy="0 0 0" />
      <mass
        value="0.014" />
      <inertia
        ixx="0.00036602"
        ixy="2.0634E-10"
        ixz="2.6755E-10"
        iyy="2.6339E-05"
        iyz="1.4418E-09"
        izz="0.00037609" />
    </inertial>
    <visual>
      <origin
        xyz="0 0 0"
        rpy="0 0 0" />
      <geometry>
        <mesh
          filename="package://sanbot_nano_urdf/meshes/neck_link.STL" />
      </geometry>
      <material
        name="">
        <color
          rgba="1 1 1 1" />
      </material>
    </visual>
    <collision>
      <origin
        xyz="0 0 0"
        rpy="0 0 0" />
      <geometry>
        <mesh
          filename="package://sanbot_nano_urdf/meshes/neck_link.STL" />
      </geometry>
    </collision>
  </link>
  <joint
    name="neck"
    type="revolute">
    <origin
      xyz="0 0.37832 0"
      rpy="0 0 0" />
    <parent
      link=" body_link" />
    <child
      link="neck_link" />
    <axis
      xyz="0 -1 0" />
    <limit
      lower="-1.5708"
      upper="1.5708"
      effort="2"
      velocity="1" />
    <dynamics
      damping="0.1"
      friction="0.1" />
  </joint>
  <link
    name="head_link">
    <inertial>
      <origin
        xyz="-0.0029281 -8.7995E-06 -0.004676"
        rpy="0 0 0" />
      <mass
        value="2.0" />
      <inertia
        ixx="0.15722"
        ixy="-9.0231E-08"
        ixz="0.011877"
        iyy="0.15278"
        iyz="-2.9604E-06"
        izz="0.15863" />
    </inertial>
    <visual>
      <origin
        xyz="0 0 0"
        rpy="0 0 0" />
      <geometry>
        <mesh
          filename="package://sanbot_nano_urdf/meshes/head_link.STL" />
      </geometry>
      <material
        name="">
        <color
          rgba="1 1 1 1" />
      </material>
    </visual>
    <collision>
      <origin
        xyz="0 0 0"
        rpy="0 0 0" />
      <geometry>
        <mesh
          filename="package://sanbot_nano_urdf/meshes/head_link.STL" />
      </geometry>
    </collision>
  </link>
  <joint
    name="head"
    type="revolute">
    <origin
      xyz="0 0.165 0"
      rpy="0 0 1.5708" />
    <parent
      link="neck_link" />
    <child
      link="head_link" />
    <axis
      xyz="0 -1 0" />
    <limit
      lower="0"
      upper="0.656"
      effort="2"
      velocity="1" />
    <dynamics
      damping="0.1"
      friction="0.1" />
  </joint>
  <link
    name="camera_chin_link">
    <inertial>
      <origin
        xyz="3.4403E-17 1.1102E-16 0.001273"
        rpy="0 0 0" />
      <mass
        value="0.002" />
      <inertia
        ixx="2.7589E-10"
        ixy="-9.0714E-27"
        ixz="-4.4884E-27"
        iyy="3.4979E-10"
        iyz="-1.3374E-26"
        izz="5.6249E-10" />
    </inertial>
    <visual>
      <origin
        xyz="0 0 0"
        rpy="0 0 0" />
      <geometry>
        <mesh
          filename="package://sanbot_nano_urdf/meshes/camera_chin_link.STL" />
      </geometry>
      <material
        name="">
        <color
          rgba="0.49804 0.49804 0.49804 1" />
      </material>
    </visual>
    <collision>
      <origin
        xyz="0 0 0"
        rpy="0 0 0" />
      <geometry>
        <mesh
          filename="package://sanbot_nano_urdf/meshes/camera_chin_link.STL" />
      </geometry>
    </collision>
  </link>
  <joint
    name="camera_chin"
    type="fixed">
    <origin
      xyz="-0.08 0 -0.1355"
      rpy="0 0 -1.5708" />
    <parent
      link="head_link" />
    <child
      link="camera_chin_link" />
    <axis
      xyz="0 0 0" />
  </joint>

  <transmission name="wheel_back_link_trans">
    <type>transmission_interface/SimpleTransmission</type>
    <joint name="wheel_back">
      <hardwareInterface>hardware_interface/VelocityJointInterface</hardwareInterface>
    </joint>
    <actuator name="wheel_back_link_motor">
      <hardwareInterface>hardware_interface/VelocityJointInterface</hardwareInterface>
      <mechanicalReduction>1</mechanicalReduction>
    </actuator>
  </transmission>
  <transmission name="wheel_left_link_trans">
    <type>transmission_interface/SimpleTransmission</type>
    <joint name="wheel_left">
      <hardwareInterface>hardware_interface/VelocityJointInterface</hardwareInterface>
    </joint>
    <actuator name="wheel_left_link_motor">
      <hardwareInterface>hardware_interface/VelocityJointInterface</hardwareInterface>
      <mechanicalReduction>1</mechanicalReduction>
    </actuator>
  </transmission>
  <transmission name="wheel_right_link_trans">
    <type>transmission_interface/SimpleTransmission</type>
    <joint name="wheel_right">
      <hardwareInterface>hardware_interface/VelocityJointInterface</hardwareInterface>
    </joint>
    <actuator name="wheel_right_link_motor">
      <hardwareInterface>hardware_interface/VelocityJointInterface</hardwareInterface>
      <mechanicalReduction>1</mechanicalReduction>
    </actuator>
  </transmission>
  <transmission name="wing_left_link_trans">
    <type>transmission_interface/SimpleTransmission</type>
    <joint name="wing_left">
      <hardwareInterface>hardware_interface/PositionJointInterface</hardwareInterface>
    </joint>
    <actuator name="wing_left_link_motor">
      <hardwareInterface>hardware_interface/PositionJointInterface</hardwareInterface>
      <mechanicalReduction>1</mechanicalReduction>
    </actuator>
  </transmission>
  <transmission name="wing_right_link_trans">
    <type>transmission_interface/SimpleTransmission</type>
    <joint name="wing_right">
      <hardwareInterface>hardware_interface/PositionJointInterface</hardwareInterface>
    </joint>
    <actuator name="wing_right_link_motor">
      <hardwareInterface>hardware_interface/PositionJointInterface</hardwareInterface>
      <mechanicalReduction>1</mechanicalReduction>
    </actuator>
  </transmission>
  <transmission name="neck_link_trans">
    <type>transmission_interface/SimpleTransmission</type>
    <joint name="neck">
      <hardwareInterface>hardware_interface/PositionJointInterface</hardwareInterface>
    </joint>
    <actuator name="neck_link_motor">
      <hardwareInterface>hardware_interface/PositionJointInterface</hardwareInterface>
      <mechanicalReduction>1</mechanicalReduction>
    </actuator>
  </transmission>
  <transmission name="head_link_trans">
    <type>transmission_interface/SimpleTransmission</type>
    <joint name="head">
      <hardwareInterface>hardware_interface/PositionJointInterface</hardwareInterface>
    </joint>
    <actuator name="head_link_motor">
      <hardwareInterface>hardware_interface/PositionJointInterface</hardwareInterface>
      <mechanicalReduction>1</mechanicalReduction>
    </actuator>
  </transmission>

  <gazebo reference="wheel_back_link">
    <selfCollide>true</selfCollide>
    <mu1>0.8</mu1>
    <mu2>0.01</mu2>
    <slip1>0.0</slip1>
    <slip2>1.0</slip2>
  </gazebo>
  <gazebo reference="wheel_left_link">
    <selfCollide>true</selfCollide>
    <mu1>0.8</mu1>
    <mu2>0.01</mu2>
    <slip1>0.0</slip1>
    <slip2>1.0</slip2>
  </gazebo>
  <gazebo reference="wheel_right_link">
    <selfCollide>true</selfCollide>
    <mu1>0.8</mu1>
    <mu2>0.01</mu2>
    <slip1>0.0</slip1>
    <slip2>1.0</slip2>
  </gazebo>
  <gazebo reference="wing_left_link">
    <selfCollide>true</selfCollide>
  </gazebo>
  <gazebo reference="wing_right_link">
    <selfCollide>true</selfCollide>
  </gazebo>
  <gazebo reference="neck_link">
    <selfCollide>true</selfCollide>
  </gazebo>
  <gazebo reference="head_link">
    <selfCollide>true</selfCollide>
  </gazebo>
  
  <gazebo reference="neck">
    <provideFeedback>true</provideFeedback>
    <implicitSpringDamper>1</implicitSpringDamper>
    <implicitDampingFactor>0.1</implicitDampingFactor>
  </gazebo>
  
  <gazebo reference="head">
    <provideFeedback>true</provideFeedback>
    <implicitSpringDamper>1</implicitSpringDamper>
    <implicitDampingFactor>0.1</implicitDampingFactor>
  </gazebo>
  
  <gazebo reference="camera_chin_link">
    <sensor type="camera" name="camera_chin">
      <pose>0 0 0 -1.5708 1.5708 0</pose>
      <always_on>true</always_on>
      <update_rate>30</update_rate>
      <visualize>true</visualize>
      <camera>
        <image>
          <width>1280</width>
          <height>720</height>
          <format>R8G8B8</format>
        </image>
      </camera>
      <plugin name="camera_controller" filename="libgazebo_ros_camera.so">
        <robotNamespace>/</robotNamespace>
        <cameraName>camera</cameraName>
        <imageTopicName>image_raw</imageTopicName>
        <cameraInfoTopicName>camera_info</cameraInfoTopicName>
        <frameName>camera_chin_link</frameName>
      </plugin>
    </sensor>
  </gazebo>

  <gazebo>
    <plugin name="control"
      filename="libgazebo_ros_control.so">
      <robotNamespace>/</robotNamespace>
    </plugin>
  </gazebo>

  <gazebo>
    <plugin name="imu_plugin" filename="libgazebo_ros_imu.so">
      <alwaysOn>true</alwaysOn>
      <bodyName>base_link</bodyName>
      <topicName>imu</topicName>
      <serviceName>imu_service</serviceName>
      <gaussianNoise>0.0</gaussianNoise>
      <updateRate>10.0</updateRate>
    </plugin>
  </gazebo>
</robot>