<?xml version="1.0" encoding="utf-8"?>
<!-- This URDF was automatically created by SolidWorks to URDF Exporter! Originally created by Stephen Brawner (brawner@gmail.com) 
     Commit Version: 1.6.0-4-g7f85cfe  Build Version: 1.6.7995.38578
     For more information, please see http://wiki.ros.org/sw_urdf_exporter -->
<robot
  name="sanbot_nano_urdf">
  <link
    name="base_link">
    <inertial>
      <origin
        xyz="1.64477253035515E-05 -5.93128846061797E-06 0.0729321766717518"
        rpy="0 0 0" />
      <mass
        value="6.0" />
      <inertia
        ixx="0.11281645397611"
        ixy="-2.49617328764964E-05"
        ixz="3.29336671339687E-05"
        iyy="0.11397342921281"
        iyz="-5.30882435321541E-07"
        izz="0.213909779379668" />
    </inertial>
    <visual>
      <origin
        xyz="0 0 0"
        rpy="0 0 0" />
      <geometry>
        <mesh
          filename="package://sanbot_nano_urdf/meshes/base_link.STL" />
      </geometry>
      <material
        name="">
        <color
          rgba="1 1 1 1" />
      </material>
    </visual>
    <collision>
      <origin
        xyz="0 0 0"
        rpy="0 0 0" />
      <geometry>
        <mesh
          filename="package://sanbot_nano_urdf/meshes/base_link.STL" />
      </geometry>
    </collision>
  </link>
  <link
    name="wheel_back_link">
    <inertial>
      <origin
        xyz="-1.95717879518165E-08 1.68817821145917E-07 0.0179686472612415"
        rpy="0 0 0" />
      <mass
        value="0.088" />
      <inertia
        ixx="9.20122787951246E-05"
        ixy="-3.94039420487444E-16"
        ixz="-1.20594183387887E-20"
        iyy="9.20122787946692E-05"
        iyz="4.01531480291635E-21"
        izz="0.000170504431903692" />
    </inertial>
    <visual>
      <origin
        xyz="0 0 0"
        rpy="0 0 0" />
      <geometry>
        <mesh
          filename="package://sanbot_nano_urdf/meshes/wheel_back_link.STL" />
      </geometry>
      <material
        name="">
        <color
          rgba="0.101960784313725 0.101960784313725 0.101960784313725 1" />
      </material>
    </visual>
    <collision>
      <origin
        xyz="0 0 0"
        rpy="0 0 0" />
      <geometry>
        <mesh
          filename="package://sanbot_nano_urdf/meshes/wheel_back_link.STL" />
      </geometry>
    </collision>
  </link>
  <joint
    name="wheel_back"
    type="continuous">
    <origin
      xyz="-0.1195 0 0.03"
      rpy="1.5707963267949 0 -1.5707963267949" />
    <parent
      link="base_link" />
    <child
      link="wheel_back_link" />
    <axis
      xyz="0 0 1" />
  </joint>
  <link
    name="wheel_left_link">
    <inertial>
      <origin
        xyz="-0.0155613556791649 -1.36414627750076E-07 -0.00898423585151899"
        rpy="0 0 0" />
      <mass
        value="0.088" />
      <inertia
        ixx="0.000150881393626606"
        ixy="-4.8466166450707E-20"
        ixz="3.39880992947803E-05"
        iyy="9.20122787944416E-05"
        iyz="7.35859872927173E-20"
        izz="0.000111635317072437" />
    </inertial>
    <visual>
      <origin
        xyz="0 0 0"
        rpy="0 0 0" />
      <geometry>
        <mesh
          filename="package://sanbot_nano_urdf/meshes/wheel_left_link.STL" />
      </geometry>
      <material
        name="">
        <color
          rgba="0.101960784313725 0.101960784313725 0.101960784313725 1" />
      </material>
    </visual>
    <collision>
      <origin
        xyz="0 0 0"
        rpy="0 0 0" />
      <geometry>
        <mesh
          filename="package://sanbot_nano_urdf/meshes/wheel_left_link.STL" />
      </geometry>
    </collision>
  </link>
  <joint
    name="wheel_left"
    type="continuous">
    <origin
      xyz="0.0597500000000005 0.10349003575224 0.03"
      rpy="1.5707963267949 0 -1.5707963267949" />
    <parent
      link="base_link" />
    <child
      link="wheel_left_link" />
    <axis
      xyz="-0.866025403784436 0 -0.500000000000004" />
  </joint>
  <link
    name="wheel_right_link">
    <inertial>
      <origin
        xyz="0.0155629154939929 2.6295644686182E-06 -0.00898153417298636"
        rpy="0 0 0" />
      <mass
        value="0.088" />
      <inertia
        ixx="0.000150881393626607"
        ixy="-1.12364214409203E-19"
        ixz="-3.39880992947797E-05"
        iyy="9.20122787944418E-05"
        iyz="-1.84547303383031E-19"
        izz="0.000111635317072436" />
    </inertial>
    <visual>
      <origin
        xyz="0 0 0"
        rpy="0 0 0" />
      <geometry>
        <mesh
          filename="package://sanbot_nano_urdf/meshes/wheel_right_link.STL" />
      </geometry>
      <material
        name="">
        <color
          rgba="0.101960784313725 0.101960784313725 0.101960784313725 1" />
      </material>
    </visual>
    <collision>
      <origin
        xyz="0 0 0"
        rpy="0 0 0" />
      <geometry>
        <mesh
          filename="package://sanbot_nano_urdf/meshes/wheel_right_link.STL" />
      </geometry>
    </collision>
  </link>
  <joint
    name="wheel_right"
    type="continuous">
    <origin
      xyz="0.0597527016785317 -0.103488475937413 0.0299975068501592"
      rpy="1.5707963267949 0 -1.5707963267949" />
    <parent
      link="base_link" />
    <child
      link="wheel_right_link" />
    <axis
      xyz="0.866025403784443 0 -0.499999999999992" />
  </joint>
  <link
    name="body_link">
    <inertial>
      <origin
        xyz="-6.50765303979052E-07 0.171159583722946 0.00531935436703976"
        rpy="0 0 0" />
      <mass
        value="10.54" />
      <inertia
        ixx="0.626295583597268"
        ixy="4.13882256953019E-06"
        ixz="1.17397507823637E-07"
        iyy="0.5835007228739"
        iyz="-0.000770846944992861"
        izz="0.656658337498849" />
    </inertial>
    <visual>
      <origin
        xyz="0 0 0"
        rpy="0 0 0" />
      <geometry>
        <mesh
          filename="package://sanbot_nano_urdf/meshes/body_link.STL" />
      </geometry>
      <material
        name="">
        <color
          rgba="1 1 1 1" />
      </material>
    </visual>
    <collision>
      <origin
        xyz="0 0 0"
        rpy="0 0 0" />
      <geometry>
        <mesh
          filename="package://sanbot_nano_urdf/meshes/body_link.STL" />
      </geometry>
    </collision>
  </link>
  <joint
    name="body"
    type="fixed">
    <origin
      xyz="0 0 0.14"
      rpy="1.5707963267949 0 -1.5707963267949" />
    <parent
      link="base_link" />
    <child
      link="body_link" />
    <axis
      xyz="0 0 0" />
  </joint>
  <link
    name="wing_left_link">
    <inertial>
      <origin
        xyz="-0.0180528514790016 -0.0603564713524469 -0.00920090040634636"
        rpy="0 0 0" />
      <mass
        value="0.09" />
      <inertia
        ixx="0.00143508347758134"
        ixy="-1.11397432746257E-05"
        ixz="-1.72108088017256E-06"
        iyy="0.000410412505557005"
        iyz="-8.69465392904125E-05"
        izz="0.00103848643600513" />
    </inertial>
    <visual>
      <origin
        xyz="0 0 0"
        rpy="0 0 0" />
      <geometry>
        <mesh
          filename="package://sanbot_nano_urdf/meshes/wing_left_link.STL" />
      </geometry>
      <material
        name="">
        <color
          rgba="1 1 1 1" />
      </material>
    </visual>
    <collision>
      <origin
        xyz="0 0 0"
        rpy="0 0 0" />
      <geometry>
        <mesh
          filename="package://sanbot_nano_urdf/meshes/wing_left_link.STL" />
      </geometry>
    </collision>
  </link>
  <joint
    name="wing_left"
    type="revolute">
    <origin
      xyz="-0.171 0.338 -0.0087685"
      rpy="0 0 0" />
    <parent
      link="body_link" />
    <child
      link="wing_left_link" />
    <axis
      xyz="1 0 0" />
    <limit
      lower="-1.5708"
      upper="3.1416"
      effort="10"
      velocity="1" />
  </joint>
  <link
    name="wing_right_link">
    <inertial>
      <origin
        xyz="0.0180596331580364 -0.060389654065786 -0.00920199725760526"
        rpy="0 0 0" />
      <mass
        value="0.09" />
      <inertia
        ixx="0.00143527781768375"
        ixy="1.11307475747432E-05"
        ixz="1.71994140484216E-06"
        iyy="0.000410538848951017"
        iyz="-8.69715731520652E-05"
        izz="0.00103855929783202" />
    </inertial>
    <visual>
      <origin
        xyz="0 0 0"
        rpy="0 0 0" />
      <geometry>
        <mesh
          filename="package://sanbot_nano_urdf/meshes/wing_right_link.STL" />
      </geometry>
      <material
        name="">
        <color
          rgba="1 1 1 1" />
      </material>
    </visual>
    <collision>
      <origin
        xyz="0 0 0"
        rpy="0 0 0" />
      <geometry>
        <mesh
          filename="package://sanbot_nano_urdf/meshes/wing_right_link.STL" />
      </geometry>
    </collision>
  </link>
  <joint
    name="wing_right"
    type="revolute">
    <origin
      xyz="0.171 0.338 -0.0087685"
      rpy="0 0 0" />
    <parent
      link="body_link" />
    <child
      link="wing_right_link" />
    <axis
      xyz="1 0 0" />
    <limit
      lower="-1.5708"
      upper="3.1416"
      effort="10"
      velocity="1" />
  </joint>
  <link
    name="neck_link">
    <inertial>
      <origin
        xyz="5.07959831374071E-08 0.0941822883771553 -2.15444560198962E-07"
        rpy="0 0 0" />
      <mass
        value="0.014" />
      <inertia
        ixx="0.000366019650270741"
        ixy="2.06341913901781E-10"
        ixz="2.67552661225935E-10"
        iyy="2.63393480841544E-05"
        iyz="1.44182677592475E-09"
        izz="0.000376086984549767" />
    </inertial>
    <visual>
      <origin
        xyz="0 0 0"
        rpy="0 0 0" />
      <geometry>
        <mesh
          filename="package://sanbot_nano_urdf/meshes/neck_link.STL" />
      </geometry>
      <material
        name="">
        <color
          rgba="1 1 1 1" />
      </material>
    </visual>
    <collision>
      <origin
        xyz="0 0 0"
        rpy="0 0 0" />
      <geometry>
        <mesh
          filename="package://sanbot_nano_urdf/meshes/neck_link.STL" />
      </geometry>
    </collision>
  </link>
  <joint
    name="head_pan"
    type="revolute">
    <origin
      xyz="0 0.37832467677926 0"
      rpy="0 0 0" />
    <parent
      link="body_link" />
    <child
      link="neck_link" />
    <axis
      xyz="0 -1 0" />
    <limit
      lower="-1.5708"
      upper="1.5708"
      effort="2"
      velocity="1" />
    <dynamics
      damping="0.1"
      friction="0.1" />
  </joint>
  <link
    name="head_link">
    <inertial>
      <origin
        xyz="-0.00292739797448505 -8.87853531190918E-06 -0.00467681669714786"
        rpy="0 0 0" />
      <mass
        value="2.0" />
      <inertia
        ixx="0.15722634471642"
        ixy="2.87198097557583E-08"
        ixz="0.011878200831867"
        iyy="0.15278436259043"
        iyz="-3.11256146657035E-06"
        izz="0.158627375620337" />
    </inertial>
    <visual>
      <origin
        xyz="0 0 0"
        rpy="0 0 0" />
      <geometry>
        <mesh
          filename="package://sanbot_nano_urdf/meshes/head_link.STL" />
      </geometry>
      <material
        name="">
        <color
          rgba="1 1 1 1" />
      </material>
    </visual>
    <collision>
      <origin
        xyz="0 0 0"
        rpy="0 0 0" />
      <geometry>
        <mesh
          filename="package://sanbot_nano_urdf/meshes/head_link.STL" />
      </geometry>
    </collision>
  </link>
  <joint
    name="head_tilt"
    type="revolute">
    <origin
      xyz="0 0.165 0"
      rpy="0 0 1.5707963267949" />
    <parent
      link="neck_link" />
    <child
      link="head_link" />
    <axis
      xyz="0 -1 0" />
    <limit
      lower="0"
      upper="0.656"
      effort="2"
      velocity="1" />
    <dynamics
      damping="0.1"
      friction="0.1" />
  </joint>
  <link
    name="camera_chin_link">
    <inertial>
      <origin
        xyz="6.47225141324598E-16 0 0.00127296486785475"
        rpy="0 0 0" />
      <mass
        value="8.42614806857185E-05" />
      <inertia
        ixx="2.75893420315291E-10"
        ixy="-5.62482498326781E-27"
        ixz="-1.65992804415805E-27"
        iyy="3.49794254771563E-10"
        iyz="-1.3314397341848E-26"
        izz="5.62491899186398E-10" />
    </inertial>
    <visual>
      <origin
        xyz="0 0 0"
        rpy="0 0 0" />
      <geometry>
        <mesh
          filename="package://sanbot_nano_urdf/meshes/camera_chin_link.STL" />
      </geometry>
      <material
        name="">
        <color
          rgba="0.498039215686275 0.498039215686275 0.498039215686275 1" />
      </material>
    </visual>
    <collision>
      <origin
        xyz="0 0 0"
        rpy="0 0 0" />
      <geometry>
        <mesh
          filename="package://sanbot_nano_urdf/meshes/camera_chin_link.STL" />
      </geometry>
    </collision>
  </link>
  <joint
    name="camera_chin"
    type="fixed">
    <origin
      xyz="-0.0799999999999998 0 -0.1355"
      rpy="0 0 -1.5707963267949" />
    <parent
      link="head_link" />
    <child
      link="camera_chin_link" />
    <axis
      xyz="0 0 0" />
  </joint>
  <link
    name="camera_forehead_link">
    <inertial>
      <origin
        xyz="0 0 -0.0014595354650945"
        rpy="0 0 0" />
      <mass
        value="0.00068843" />
      <inertia
        ixx="1.29448568366983E-08"
        ixy="-3.34742343723264E-25"
        ixz="1.27649608189021E-24"
        iyy="1.58316081826464E-08"
        iyz="-2.23290707108769E-25"
        izz="2.79154477143972E-08" />
    </inertial>
    <visual>
      <origin
        xyz="0 0 0"
        rpy="0 0 0" />
      <geometry>
        <mesh
          filename="package://sanbot_nano_urdf/meshes/camera_forehead_link.STL" />
      </geometry>
      <material
        name="">
        <color
          rgba="0.498039215686275 0.498039215686275 0.498039215686275 1" />
      </material>
    </visual>
    <collision>
      <origin
        xyz="0 0 0"
        rpy="0 0 0" />
      <geometry>
        <mesh
          filename="package://sanbot_nano_urdf/meshes/camera_forehead_link.STL" />
      </geometry>
    </collision>
  </link>
  <joint
    name="camera_forehead"
    type="fixed">
    <origin
      xyz="0.10192 -0.085 -0.136"
      rpy="-3.1416 0 1.5708" />
    <parent
      link="head_link" />
    <child
      link="camera_forehead_link" />
    <axis
      xyz="0 0 0" />
  </joint>
  <link
    name="camera_depth_link">
    <inertial>
      <origin
        xyz="0.00047727 9.1661E-06 -0.00047167"
        rpy="0 0 0" />
      <mass
        value="0.0024849" />
      <inertia
        ixx="5.9941E-08"
        ixy="5.8028E-10"
        ixz="-1.1524E-09"
        iyy="1.7495E-06"
        iyz="-2.2131E-11"
        izz="1.8074E-06" />
    </inertial>
    <visual>
      <origin
        xyz="0 0 0"
        rpy="0 0 0" />
      <geometry>
        <mesh
          filename="package://sanbot_nano_urdf/meshes/camera_depth_link.STL" />
      </geometry>
      <material
        name="">
        <color
          rgba="0.49804 0.49804 0.49804 1" />
      </material>
    </visual>
    <collision>
      <origin
        xyz="0 0 0"
        rpy="0 0 0" />
      <geometry>
        <mesh
          filename="package://sanbot_nano_urdf/meshes/camera_depth_link.STL" />
      </geometry>
    </collision>
  </link>
  <joint
    name="camera_depth"
    type="fixed">
    <origin
      xyz="0.10692 0 -0.135"
      rpy="-3.1416 0 1.5708" />
    <parent
      link="head_link" />
    <child
      link="camera_depth_link" />
    <axis
      xyz="0 0 0" />
  </joint>
  <link
    name="ir_13_link">
    <inertial>
      <origin
        xyz="-1.5771E-18 5.5511E-17 0.005"
        rpy="0 0 0" />
      <mass
        value="0.001" />
      <inertia
        ixx="1.6667E-08"
        ixy="2.0305E-24"
        ixz="2.1684E-25"
        iyy="1.6667E-08"
        iyz="1.6918E-24"
        izz="1.6667E-08" />
    </inertial>
    <visual>
      <origin
        xyz="0 0 0"
        rpy="0 0 0" />
      <geometry>
        <mesh
          filename="package://sanbot_nano_urdf/meshes/ir_13_link.STL" />
      </geometry>
      <material
        name="">
        <color
          rgba="0.10196 0.10196 0.10196 1" />
      </material>
    </visual>
    <collision>
      <origin
        xyz="0 0 0"
        rpy="0 0 0" />
      <geometry>
        <mesh
          filename="package://sanbot_nano_urdf/meshes/ir_13_link.STL" />
      </geometry>
    </collision>
  </link>
  <joint
    name="ir_13"
    type="fixed">
    <origin
      xyz="0 0.23 -0.16"
      rpy="0 0 0" />
    <parent
      link="body_link" />
    <child
      link="ir_13_link" />
    <axis
      xyz="0 0 0" />
  </joint>

  <transmission name="wheel_back_link_trans">
    <type>transmission_interface/SimpleTransmission</type>
    <joint name="wheel_back">
      <hardwareInterface>hardware_interface/VelocityJointInterface</hardwareInterface>
    </joint>
    <actuator name="wheel_back_link_motor">
      <hardwareInterface>hardware_interface/VelocityJointInterface</hardwareInterface>
      <mechanicalReduction>1</mechanicalReduction>
    </actuator>
  </transmission>
  <transmission name="wheel_left_link_trans">
    <type>transmission_interface/SimpleTransmission</type>
    <joint name="wheel_left">
      <hardwareInterface>hardware_interface/VelocityJointInterface</hardwareInterface>
    </joint>
    <actuator name="wheel_left_link_motor">
      <hardwareInterface>hardware_interface/VelocityJointInterface</hardwareInterface>
      <mechanicalReduction>1</mechanicalReduction>
    </actuator>
  </transmission>
  <transmission name="wheel_right_link_trans">
    <type>transmission_interface/SimpleTransmission</type>
    <joint name="wheel_right">
      <hardwareInterface>hardware_interface/VelocityJointInterface</hardwareInterface>
    </joint>
    <actuator name="wheel_right_link_motor">
      <hardwareInterface>hardware_interface/VelocityJointInterface</hardwareInterface>
      <mechanicalReduction>1</mechanicalReduction>
    </actuator>
  </transmission>
  <transmission name="wing_left_link_trans">
    <type>transmission_interface/SimpleTransmission</type>
    <joint name="wing_left">
      <hardwareInterface>hardware_interface/PositionJointInterface</hardwareInterface>
    </joint>
    <actuator name="wing_left_link_motor">
      <hardwareInterface>hardware_interface/PositionJointInterface</hardwareInterface>
      <mechanicalReduction>1</mechanicalReduction>
    </actuator>
  </transmission>
  <transmission name="wing_right_link_trans">
    <type>transmission_interface/SimpleTransmission</type>
    <joint name="wing_right">
      <hardwareInterface>hardware_interface/PositionJointInterface</hardwareInterface>
    </joint>
    <actuator name="wing_right_link_motor">
      <hardwareInterface>hardware_interface/PositionJointInterface</hardwareInterface>
      <mechanicalReduction>1</mechanicalReduction>
    </actuator>
  </transmission>
  <transmission name="neck_link_trans">
    <type>transmission_interface/SimpleTransmission</type>
    <joint name="head_pan">
      <hardwareInterface>hardware_interface/PositionJointInterface</hardwareInterface>
    </joint>
    <actuator name="neck_link_motor">
      <hardwareInterface>hardware_interface/PositionJointInterface</hardwareInterface>
      <mechanicalReduction>1</mechanicalReduction>
    </actuator>
  </transmission>
  <transmission name="head_link_trans">
    <type>transmission_interface/SimpleTransmission</type>
    <joint name="head_tilt">
      <hardwareInterface>hardware_interface/PositionJointInterface</hardwareInterface>
    </joint>
    <actuator name="head_link_motor">
      <hardwareInterface>hardware_interface/PositionJointInterface</hardwareInterface>
      <mechanicalReduction>1</mechanicalReduction>
    </actuator>
  </transmission>

  <gazebo reference="wheel_back_link">
    <selfCollide>true</selfCollide>
    <turnGravityOff>true</turnGravityOff>
  </gazebo>
  <gazebo reference="wheel_left_link">
    <selfCollide>true</selfCollide>
    <turnGravityOff>true</turnGravityOff>
  </gazebo>
  <gazebo reference="wheel_right_link">
    <selfCollide>true</selfCollide>
    <turnGravityOff>true</turnGravityOff>
  </gazebo>
  <gazebo reference="wing_left_link">
    <selfCollide>true</selfCollide>
    <turnGravityOff>true</turnGravityOff>
  </gazebo>
  <gazebo reference="wing_right_link">
    <selfCollide>true</selfCollide>
    <turnGravityOff>true</turnGravityOff>
  </gazebo>
  <gazebo reference="neck_link">
    <selfCollide>true</selfCollide>
    <turnGravityOff>true</turnGravityOff>
  </gazebo>
  <gazebo reference="head_link">
    <selfCollide>true</selfCollide>
    <turnGravityOff>true</turnGravityOff>
  </gazebo>
  <gazebo reference="base_link">
    <selfCollide>true</selfCollide>
    <turnGravityOff>true</turnGravityOff>
  </gazebo>
  <gazebo reference="body_link">
    <selfCollide>true</selfCollide>
    <turnGravityOff>true</turnGravityOff>
  </gazebo>
  
  <gazebo reference="camera_chin_link">
    <sensor type="camera" name="camera_chin">
      <pose>0 0 0 -1.5708 1.5708 0</pose>
      <always_on>true</always_on>
      <update_rate>30</update_rate>
      <camera>
        <image>
          <width>1280</width>
          <height>720</height>
          <format>R8G8B8</format>
        </image>
      </camera>
      <plugin name="camera_controller" filename="libgazebo_ros_camera.so">
        <robotNamespace>/</robotNamespace>
        <cameraName>camera_chin</cameraName>
        <imageTopicName>image_raw</imageTopicName>
        <frameName>camera_chin_link</frameName>
      </plugin>
    </sensor>
  </gazebo>

  <gazebo reference="camera_forehead_link">
    <sensor type="camera" name="camera_forehead">
      <pose>0 0 0 -1.5708 -1.5708 0</pose>
      <always_on>true</always_on>
      <update_rate>30</update_rate>
      <camera>
        <image>
          <width>1280</width>
          <height>720</height>
          <format>R8G8B8</format>
        </image>
      </camera>
      <plugin name="camera_controller" filename="libgazebo_ros_camera.so">
        <robotNamespace>/</robotNamespace>
        <cameraName>camera_forehead</cameraName>
        <imageTopicName>image_raw</imageTopicName>
        <frameName>camera_forehead_link</frameName>
      </plugin>
    </sensor>
  </gazebo>

  <gazebo reference="camera_depth_link">
    <sensor type="depth" name="camera_depth">
      <pose>0 0 0 -1.5708 -1.5708 0</pose>
      <always_on>true</always_on>
      <update_rate>30</update_rate>
      <camera>
        <image>
          <width>1280</width>
          <height>720</height>
          <format>R8G8B8</format>
        </image>
      </camera>
      <plugin name="camera_depth_controller" filename="libgazebo_ros_depth_camera.so">
        <cameraName>camera_depth</cameraName>
        <imageTopicName>depth/image_raw</imageTopicName>
        <frameName>camera_depth_link</frameName>
      </plugin>
    </sensor>
  </gazebo>
  
  <gazebo>
    <plugin name="control"
      filename="libgazebo_ros_control.so">
    </plugin>
  </gazebo>

  <gazebo>
    <plugin name="imu_plugin" filename="libgazebo_ros_imu.so">
      <alwaysOn>true</alwaysOn>
      <bodyName>base_link</bodyName>
      <topicName>imu</topicName>
      <serviceName>imu_service</serviceName>
      <gaussianNoise>0.0</gaussianNoise>
      <updateRate>10.0</updateRate>
    </plugin>
  </gazebo>

  <gazebo>
    <plugin name="object_controller" filename="libgazebo_ros_planar_move.so">
      <commandTopic>cmd_vel</commandTopic>
      <odometryTopic>odom</odometryTopic>
      <odometryFrame>odom</odometryFrame>
      <odometryRate>10.0</odometryRate>
      <robotBaseFrame>base_link</robotBaseFrame>
    </plugin>
  </gazebo>
</robot>