<?xml version="1.0" encoding="utf-8"?>
<!-- This URDF was automatically created by SolidWorks to URDF Exporter! Originally created by Stephen Brawner (brawner@gmail.com) 
     Commit Version: 1.6.0-4-g7f85cfe  Build Version: 1.6.7995.38578
     For more information, please see http://wiki.ros.org/sw_urdf_exporter -->
<robot
  name="sanbot_nano_urdf">
  <link
    name="base_link">
    <inertial>
      <origin
        xyz="-1.64489988501229E-05 5.93174771999595E-06 0.0729273707631982"
        rpy="0 0 0" />
      <mass
        value="6.0" />
      <inertia
        ixx="0.112814848349768"
        ixy="-2.49617329443895E-05"
        ixz="-3.29240508334015E-05"
        iyy="0.113971823528271"
        iyz="5.30871216894326E-07"
        izz="0.213909762654804" />
    </inertial>
    <visual>
      <origin
        xyz="0 0 0"
        rpy="0 0 0" />
      <geometry>
        <mesh
          filename="package://sanbot_nano_urdf/meshes/base_link.STL" />
      </geometry>
      <material
        name="">
        <color
          rgba="1 1 1 1" />
      </material>
    </visual>
    <collision>
      <origin
        xyz="0 0 0"
        rpy="0 0 0" />
      <geometry>
        <mesh
          filename="package://sanbot_nano_urdf/meshes/base_link.STL" />
      </geometry>
    </collision>
  </link>
  <link
    name="wheel_1_link">
    <inertial>
      <origin
        xyz="-1.95717879473657E-08 1.68817821152856E-07 0.0179686472612416"
        rpy="0 0 0" />
      <mass
        value="0.088" />
      <inertia
        ixx="9.20122787951245E-05"
        ixy="-3.94042268161542E-16"
        ixz="-1.19493109835992E-20"
        iyy="9.20122787946692E-05"
        iyz="3.93901873622923E-21"
        izz="0.000170504431903692" />
    </inertial>
    <visual>
      <origin
        xyz="0 0 0"
        rpy="0 0 0" />
      <geometry>
        <mesh
          filename="package://sanbot_nano_urdf/meshes/wheel_1_link.STL" />
      </geometry>
      <material
        name="">
        <color
          rgba="0.101960784313725 0.101960784313725 0.101960784313725 1" />
      </material>
    </visual>
    <collision>
      <origin
        xyz="0 0 0"
        rpy="0 0 0" />
      <geometry>
        <mesh
          filename="package://sanbot_nano_urdf/meshes/wheel_1_link.STL" />
      </geometry>
    </collision>
  </link>
  <joint
    name="wheel_1"
    type="continuous">
    <origin
      xyz="0.1195 0 0.03"
      rpy="1.5707963267949 0 1.5707963267949" />
    <parent
      link="base_link" />
    <child
      link="wheel_1_link" />
    <axis
      xyz="0 0 1" />
  </joint>
  <link
    name="wheel_2_link">
    <inertial>
      <origin
        xyz="-0.0155613556791648 -1.36414627743137E-07 -0.00898423585151896"
        rpy="0 0 0" />
      <mass
        value="0.088" />
      <inertia
        ixx="0.000150881393626606"
        ixy="-4.78044219606646E-20"
        ixz="3.39880992947803E-05"
        iyy="9.20122787944416E-05"
        iyz="7.35859872927173E-20"
        izz="0.000111635317072437" />
    </inertial>
    <visual>
      <origin
        xyz="0 0 0"
        rpy="0 0 0" />
      <geometry>
        <mesh
          filename="package://sanbot_nano_urdf/meshes/wheel_2_link.STL" />
      </geometry>
      <material
        name="">
        <color
          rgba="0.101960784313725 0.101960784313725 0.101960784313725 1" />
      </material>
    </visual>
    <collision>
      <origin
        xyz="0 0 0"
        rpy="0 0 0" />
      <geometry>
        <mesh
          filename="package://sanbot_nano_urdf/meshes/wheel_2_link.STL" />
      </geometry>
    </collision>
  </link>
  <joint
    name="wheel_2"
    type="continuous">
    <origin
      xyz="-0.0597500000000005 -0.10349003575224 0.03"
      rpy="1.5707963267949 0 1.5707963267949" />
    <parent
      link="base_link" />
    <child
      link="wheel_2_link" />
    <axis
      xyz="-0.866025403784436 0 -0.500000000000004" />
  </joint>
  <link
    name="wheel_3_link">
    <inertial>
      <origin
        xyz="0.0155629154939929 2.62956446861126E-06 -0.00898153417298636"
        rpy="0 0 0" />
      <mass
        value="0.088" />
      <inertia
        ixx="0.000150881393626607"
        ixy="-1.12575972646017E-19"
        ixz="-3.39880992947797E-05"
        iyy="9.20122787944418E-05"
        iyz="-1.85447275889488E-19"
        izz="0.000111635317072436" />
    </inertial>
    <visual>
      <origin
        xyz="0 0 0"
        rpy="0 0 0" />
      <geometry>
        <mesh
          filename="package://sanbot_nano_urdf/meshes/wheel_3_link.STL" />
      </geometry>
      <material
        name="">
        <color
          rgba="0.101960784313725 0.101960784313725 0.101960784313725 1" />
      </material>
    </visual>
    <collision>
      <origin
        xyz="0 0 0"
        rpy="0 0 0" />
      <geometry>
        <mesh
          filename="package://sanbot_nano_urdf/meshes/wheel_3_link.STL" />
      </geometry>
    </collision>
  </link>
  <joint
    name="wheel_3"
    type="continuous">
    <origin
      xyz="-0.0597527016785317 0.103488475937413 0.0299975068501592"
      rpy="1.5707963267949 0 1.5707963267949" />
    <parent
      link="base_link" />
    <child
      link="wheel_3_link" />
    <axis
      xyz="0.866025403784443 0 -0.499999999999992" />
  </joint>
  <link
    name=" body_link">
    <inertial>
      <origin
        xyz="-6.50785024484016E-07 0.171149169150873 0.00532525299172729"
        rpy="0 0 0" />
      <mass
        value="10.54" />
      <inertia
        ixx="0.626323246289364"
        ixy="4.13879140447269E-06"
        ixz="1.17478367883546E-07"
        iyy="0.583524660915438"
        iyz="-0.000761556134756353"
        izz="0.656661718521782" />
    </inertial>
    <visual>
      <origin
        xyz="0 0 0"
        rpy="0 0 0" />
      <geometry>
        <mesh
          filename="package://sanbot_nano_urdf/meshes/ body_link.STL" />
      </geometry>
      <material
        name="">
        <color
          rgba="1 1 1 1" />
      </material>
    </visual>
    <collision>
      <origin
        xyz="0 0 0"
        rpy="0 0 0" />
      <geometry>
        <mesh
          filename="package://sanbot_nano_urdf/meshes/ body_link.STL" />
      </geometry>
    </collision>
  </link>
  <joint
    name="body"
    type="fixed">
    <origin
      xyz="0 0 0.14"
      rpy="1.5708 0 1.5708" />
    <parent
      link="base_link" />
    <child
      link=" body_link" />
    <axis
      xyz="0 0 0" />
  </joint>
  <link
    name="wing_left_link">
    <inertial>
      <origin
        xyz="-0.0179312866430201 -0.0593868885677621 -0.00912733593643051"
        rpy="0 0 0" />
      <mass
        value="0.09" />
      <inertia
        ixx="0.00143164539238941"
        ixy="-1.11934742392438E-05"
        ixz="-1.72035457093397E-06"
        iyy="0.000407682728510548"
        iyz="-8.67059533546971E-05"
        izz="0.00103773370987531" />
    </inertial>
    <visual>
      <origin
        xyz="0 0 0"
        rpy="0 0 0" />
      <geometry>
        <mesh
          filename="package://sanbot_nano_urdf/meshes/wing_left_link.STL" />
      </geometry>
      <material
        name="">
        <color
          rgba="1 1 1 1" />
      </material>
    </visual>
    <collision>
      <origin
        xyz="0 0 0"
        rpy="0 0 0" />
      <geometry>
        <mesh
          filename="package://sanbot_nano_urdf/meshes/wing_left_link.STL" />
      </geometry>
    </collision>
  </link>
  <joint
    name="wing_left"
    type="revolute">
    <origin
      xyz="-0.171 0.338 -0.0087685"
      rpy="0 0 0" />
    <parent
      link=" body_link" />
    <child
      link="wing_left_link" />
    <axis
      xyz="1 0 0" />
    <limit
      lower="-1.5708"
      upper="3.1416"
      effort="10"
      velocity="1" />
  </joint>
  <link
    name="wing_right_link">
    <inertial>
      <origin
        xyz="0.01793128704352 -0.0593868388671655 -0.00912708279608063"
        rpy="0 0 0" />
      <mass
        value="0.09" />
      <inertia
        ixx="0.00143165741032644"
        ixy="1.11938578172386E-05"
        ixz="1.72039812166924E-06"
        iyy="0.00040768314806387"
        iyz="-8.67074565020371E-05"
        izz="0.00103774537493465" />
    </inertial>
    <visual>
      <origin
        xyz="0 0 0"
        rpy="0 0 0" />
      <geometry>
        <mesh
          filename="package://sanbot_nano_urdf/meshes/wing_right_link.STL" />
      </geometry>
      <material
        name="">
        <color
          rgba="1 1 1 1" />
      </material>
    </visual>
    <collision>
      <origin
        xyz="0 0 0"
        rpy="0 0 0" />
      <geometry>
        <mesh
          filename="package://sanbot_nano_urdf/meshes/wing_right_link.STL" />
      </geometry>
    </collision>
  </link>
  <joint
    name="wing_right"
    type="revolute">
    <origin
      xyz="0.171 0.338 -0.0087685"
      rpy="0 0 0" />
    <parent
      link=" body_link" />
    <child
      link="wing_right_link" />
    <axis
      xyz="1 0 0" />
    <limit
      lower="-1.5708"
      upper="3.1416"
      effort="10"
      velocity="1" />
  </joint>
  <link
    name="neck_link">
    <inertial>
      <origin
        xyz="5.07959831122588E-08 0.0941822883771556 -2.1544456022655E-07"
        rpy="0 0 0" />
      <mass
        value="0.014" />
      <inertia
        ixx="0.00036601965027074"
        ixy="2.06341914063831E-10"
        ixz="2.67552661174392E-10"
        iyy="2.63393480841545E-05"
        iyz="1.44182677610015E-09"
        izz="0.000376086984549767" />
    </inertial>
    <visual>
      <origin
        xyz="0 0 0"
        rpy="0 0 0" />
      <geometry>
        <mesh
          filename="package://sanbot_nano_urdf/meshes/neck_link.STL" />
      </geometry>
      <material
        name="">
        <color
          rgba="1 1 1 1" />
      </material>
    </visual>
    <collision>
      <origin
        xyz="0 0 0"
        rpy="0 0 0" />
      <geometry>
        <mesh
          filename="package://sanbot_nano_urdf/meshes/neck_link.STL" />
      </geometry>
    </collision>
  </link>
  <joint
    name="neck"
    type="revolute">
    <origin
      xyz="0 0.37832 0"
      rpy="0 0 0" />
    <parent
      link=" body_link" />
    <child
      link="neck_link" />
    <axis
      xyz="0 -1 0" />
    <limit
      lower="-1.5708"
      upper="1.5708"
      effort="2"
      velocity="1" />
    <dynamics
      damping="0.1"
      friction="0.1" />
  </joint>
  <link
    name="head_link">
    <inertial>
      <origin
        xyz="-0.00325390919240132 -9.40533470818674E-06 -0.00409321699192244"
        rpy="0 0 0" />
      <mass
        value="2.0" />
      <inertia
        ixx="0.156722893894616"
        ixy="-1.60649183489357E-07"
        ixz="0.0117916077009891"
        iyy="0.152397333942896"
        iyz="-1.22877482657848E-06"
        izz="0.158064847117321" />
    </inertial>
    <visual>
      <origin
        xyz="0 0 0"
        rpy="0 0 0" />
      <geometry>
        <mesh
          filename="package://sanbot_nano_urdf/meshes/head_link.STL" />
      </geometry>
      <material
        name="">
        <color
          rgba="1 1 1 1" />
      </material>
    </visual>
    <collision>
      <origin
        xyz="0 0 0"
        rpy="0 0 0" />
      <geometry>
        <mesh
          filename="package://sanbot_nano_urdf/meshes/head_link.STL" />
      </geometry>
    </collision>
  </link>
  <joint
    name="head"
    type="revolute">
    <origin
      xyz="0 0.165 0"
      rpy="0 0 1.5708" />
    <parent
      link="neck_link" />
    <child
      link="head_link" />
    <axis
      xyz="0 -1 0" />
    <limit
      lower="0"
      upper="0.656"
      effort="2"
      velocity="1" />
    <dynamics
      damping="0.1"
      friction="0.1" />
  </joint>
  <link
    name="camera_chin_link">
    <inertial>
      <origin
        xyz="3.4406E-17 1.1102E-16 0.001273"
        rpy="0 0 0" />
      <mass
        value="0.001" />
      <inertia
        ixx="2.7589E-10"
        ixy="-9.0714E-27"
        ixz="-3.6294E-27"
        iyy="3.4979E-10"
        iyz="-1.3293E-26"
        izz="5.6249E-10" />
    </inertial>
    <visual>
      <origin
        xyz="0 0 0"
        rpy="0 0 0" />
      <geometry>
        <mesh
          filename="package://sanbot_nano_urdf/meshes/camera_chin_link.STL" />
      </geometry>
      <material
        name="">
        <color
          rgba="0.49804 0.49804 0.49804 1" />
      </material>
    </visual>
    <collision>
      <origin
        xyz="0 0 0"
        rpy="0 0 0" />
      <geometry>
        <mesh
          filename="package://sanbot_nano_urdf/meshes/camera_chin_link.STL" />
      </geometry>
    </collision>
  </link>
  <joint
    name="camera_chin"
    type="fixed">
    <origin
      xyz="-0.08 0 -0.1355"
      rpy="0 0 -1.5708" />
    <parent
      link="head_link" />
    <child
      link="camera_chin_link" />
    <axis
      xyz="0 0 0" />
  </joint>
  <link
    name="giroscope_link">
    <inertial>
      <origin
        xyz="8.6736E-19 0.005 2.647E-19"
        rpy="0 0 0" />
      <mass
        value="0.001" />
      <inertia
        ixx="1.6667E-08"
        ixy="0"
        ixz="1.1029E-24"
        iyy="1.6667E-08"
        iyz="0"
        izz="1.6667E-08" />
    </inertial>
    <visual>
      <origin
        xyz="0 0 0"
        rpy="0 0 0" />
      <geometry>
        <mesh
          filename="package://sanbot_nano_urdf/meshes/giroscope_link.STL" />
      </geometry>
      <material
        name="">
        <color
          rgba="0.77647 0.75686 0.73725 1" />
      </material>
    </visual>
    <collision>
      <origin
        xyz="0 0 0"
        rpy="0 0 0" />
      <geometry>
        <mesh
          filename="package://sanbot_nano_urdf/meshes/giroscope_link.STL" />
      </geometry>
    </collision>
  </link>
  <joint
    name="giroscope"
    type="fixed">
    <origin
      xyz="0 0 0.13"
      rpy="1.5708 0 1.5708" />
    <parent
      link="base_link" />
    <child
      link="giroscope_link" />
    <axis
      xyz="0 0 0" />
  </joint>

  <transmission name="wheel_1_link_trans">
    <type>transmission_interface/SimpleTransmission</type>
    <joint name="wheel_1">
      <hardwareInterface>hardware_interface/PositionJointInterface</hardwareInterface>
    </joint>
    <actuator name="wheel_1_link_motor">
      <hardwareInterface>hardware_interface/PositionJointInterface</hardwareInterface>
      <mechanicalReduction>1</mechanicalReduction>
    </actuator>
  </transmission>
  <transmission name="wheel_2_link_trans">
    <type>transmission_interface/SimpleTransmission</type>
    <joint name="wheel_2">
      <hardwareInterface>hardware_interface/PositionJointInterface</hardwareInterface>
    </joint>
    <actuator name="wheel_2_link_motor">
      <hardwareInterface>hardware_interface/PositionJointInterface</hardwareInterface>
      <mechanicalReduction>1</mechanicalReduction>
    </actuator>
  </transmission>
  <transmission name="wheel_3_link_trans">
    <type>transmission_interface/SimpleTransmission</type>
    <joint name="wheel_3">
      <hardwareInterface>hardware_interface/PositionJointInterface</hardwareInterface>
    </joint>
    <actuator name="wheel_3_link_motor">
      <hardwareInterface>hardware_interface/PositionJointInterface</hardwareInterface>
      <mechanicalReduction>1</mechanicalReduction>
    </actuator>
  </transmission>
  <transmission name="wing_left_link_trans">
    <type>transmission_interface/SimpleTransmission</type>
    <joint name="wing_left">
      <hardwareInterface>hardware_interface/PositionJointInterface</hardwareInterface>
    </joint>
    <actuator name="wing_left_link_motor">
      <hardwareInterface>hardware_interface/PositionJointInterface</hardwareInterface>
      <mechanicalReduction>1</mechanicalReduction>
    </actuator>
  </transmission>
  <transmission name="wing_right_link_trans">
    <type>transmission_interface/SimpleTransmission</type>
    <joint name="wing_right">
      <hardwareInterface>hardware_interface/PositionJointInterface</hardwareInterface>
    </joint>
    <actuator name="wing_right_link_motor">
      <hardwareInterface>hardware_interface/PositionJointInterface</hardwareInterface>
      <mechanicalReduction>1</mechanicalReduction>
    </actuator>
  </transmission>
  <transmission name="neck_link_trans">
    <type>transmission_interface/SimpleTransmission</type>
    <joint name="neck">
      <hardwareInterface>hardware_interface/PositionJointInterface</hardwareInterface>
    </joint>
    <actuator name="neck_link_motor">
      <hardwareInterface>hardware_interface/PositionJointInterface</hardwareInterface>
      <mechanicalReduction>1</mechanicalReduction>
    </actuator>
  </transmission>
  <transmission name="head_link_trans">
    <type>transmission_interface/SimpleTransmission</type>
    <joint name="head">
      <hardwareInterface>hardware_interface/PositionJointInterface</hardwareInterface>
    </joint>
    <actuator name="head_link_motor">
      <hardwareInterface>hardware_interface/PositionJointInterface</hardwareInterface>
      <mechanicalReduction>1</mechanicalReduction>
    </actuator>
  </transmission>

  <gazebo reference="wheel_1_link">
    <selfCollide>true</selfCollide>
  </gazebo>
  <gazebo reference="wheel_2_link">
    <selfCollide>true</selfCollide>
  </gazebo>
  <gazebo reference="wheel_3_link">
    <selfCollide>true</selfCollide>
  </gazebo>
  <gazebo reference="wing_left_link">
    <selfCollide>true</selfCollide>
  </gazebo>
  <gazebo reference="wing_right_link">
    <selfCollide>true</selfCollide>
  </gazebo>
  <gazebo reference="neck_link">
    <selfCollide>true</selfCollide>
  </gazebo>
  <gazebo reference="head_link">
    <selfCollide>true</selfCollide>
  </gazebo>
  
  <!-- Configurações específicas do Gazebo para as juntas da cabeça -->
  <gazebo reference="neck">
    <provideFeedback>true</provideFeedback>
    <implicitSpringDamper>1</implicitSpringDamper>
    <implicitDampingFactor>0.1</implicitDampingFactor>
  </gazebo>
  
  <gazebo reference="head">
    <provideFeedback>true</provideFeedback>
    <implicitSpringDamper>1</implicitSpringDamper>
    <implicitDampingFactor>0.1</implicitDampingFactor>
  </gazebo>
  
  <gazebo reference="camera_chin_link">
    <sensor type="camera" name="camera_chin">
      <pose>0 0 0 -1.5708 1.5708 0</pose>
      <always_on>true</always_on>
      <update_rate>30</update_rate>
      <visualize>true</visualize>
      <camera>
        <horizontal_fov>1.3962634</horizontal_fov>
        <image>
          <width>1280</width>
          <height>720</height>
          <format>R8G8B8</format>
        </image>
        <clip>
          <near>0.02</near>
          <far>50</far>
        </clip>
      </camera>
      <plugin name="camera_controller" filename="libgazebo_ros_camera.so">
        <robotNamespace>/</robotNamespace>
        <cameraName>camera</cameraName>
        <imageTopicName>image_raw</imageTopicName>
        <cameraInfoTopicName>camera_info</cameraInfoTopicName>
        <frameName>camera_chin_link</frameName>
      </plugin>
    </sensor>
  </gazebo>

  <gazebo>
    <plugin name="control"
      filename="libgazebo_ros_control.so">
      <robotNamespace>/</robotNamespace>
    </plugin>
  </gazebo>

  <gazebo>
    <plugin name="imu_plugin" filename="libgazebo_ros_imu.so">
      <alwaysOn>true</alwaysOn>
      <bodyName>base_link</bodyName>
      <topicName>imu</topicName>
      <serviceName>imu_service</serviceName>
      <gaussianNoise>0.0</gaussianNoise>
      <updateRate>20.0</updateRate>
    </plugin>
  </gazebo>
</robot>